Workbook
Name AdICOS: Ref!$AJ$47
Name AdS: Ref!$AJ$3:$AJ$5
Name AdvFee: 'Inputs & Summary'!$C$98
Name AFR: 'Inputs & Summary'!$C$63
Name AICOPrFee: 'Inputs & Summary'!$C$87
Name AnnAge: 'Inputs & Summary'!$W$68
Name Category: 'Inputs & Summary'!$C$12
Name CDSCP: 'Inputs & Summary'!$C$16
Name CDSCPSel: 'Inputs & Summary'!$C$15
Name CGR: 'Inputs & Summary'!$C$62
Name CLPrem: 'Inputs & Summary'!$C$48
Name Compact: Ref!$AG$68:$AI$118
Name EICRInd: 'Inputs & Summary'!$C$84
Name EICRRate: 'Inputs & Summary'!$C$85
Name Election: 'Inputs & Summary'!$C$40
Name Focus: 'Inputs & Summary'!$C$54
Name FWD: 'Inputs & Summary'!$C$71
Name GIRM1: 'Inputs & Summary'!$C$93
Name GIRM2: 'Inputs & Summary'!$C$94
Name GMABC: 'Inputs & Summary'!$C$66
Name GMABR: 'Inputs & Summary'!$C$67
Name GMIR: 'Inputs & Summary'!$C$64
Name GMWBFee: 'Inputs & Summary'!$C$70
Name ICP: 'Inputs & Summary'!$C$92
Name ICR: 'Inputs & Summary'!$C$91
Name IED: 'Inputs & Summary'!$C$57
Name InPrem: 'Inputs & Summary'!$C$49
Name InS: Ref!$AJ$6:$AJ$25
Name IPI: 'Inputs & Summary'!$C$101
Name ISD: 'Inputs & Summary'!$C$53
Name IssAge1: 'Inputs & Summary'!$C$34
Name IssAge2: 'Inputs & Summary'!$C$35
Name LBInd: 'Inputs & Summary'!$C$69
Name LIADur: 'Inputs & Summary'!$C$73
Name LIB: Ref!$AH$54
Name LIC: Ref!$AI$54
Name LIMLIPMF: Ref!$AJ$54:$AJ$55
Name LIPFLIPMF: Ref!$AK$54:$AK$55
Name LivBen: 'Inputs & Summary'!$C$17
Name MatAge: 'Inputs & Summary'!$C$36
Name MaxIGP: 'Inputs & Summary'!$C$102
Name MCIR: 'Inputs & Summary'!$C$21
Name MCIRInd: 'Inputs & Summary'!$C$20
Name ModReg: Ref!$AG$68:$AJ$118
Name MWVBasis: 'Inputs & Summary'!$C$59
Name MWVRate: 'Inputs & Summary'!$C$60
Name NIRM1: 'Inputs & Summary'!$C$95
Name NIRM2: 'Inputs & Summary'!$C$96
Name None: Ref!$AG$54
Name OMaxR: 'Inputs & Summary'!$C$89
Name OMR: 'Inputs & Summary'!$C$88
Name PFED: 'Inputs & Summary'!$C$55
Name PoI5N: Ref!$AJ$26:$AJ$27
Name PoIPN: Ref!$AJ$28:$AJ$29
Name PoSS: Ref!$AJ$30:$AJ$34
Name PremEnh: 'Inputs & Summary'!$C$51
Name Product: 'Inputs & Summary'!$C$14
Name Projection: 'Inputs & Summary'!$C$56
Name PTab: 'Inputs & Summary'!$C$13
Name ResetDur: 'Inputs & Summary'!$C$100

Sheet Report
B2: ="Corebridge "&Product&" ‒ Hypothetical Illustration for "&$C$10 -> Corebridge Power Index Plus ‒ Hypothetical Illustration for Valued Client | P2: ="Corebridge "&Product&" ‒ Hypothetical Illustration for "&$C$10 -> Corebridge Power Index Plus ‒ Hypothetical Illustration for Valued Client
B4: Profile & Income Details | E4: Interest Crediting Strategies | P4: =IF(OR(Summary="Favorable",Summary="Unfavorable"),"Interest Crediting Strategy Level Summary","Contract Level Summary") -> Contract Level Summary
F5: Fixed Rate | G5: Cap | H5: ParRate | I5: Triggered Rate | J5: Spread | K5: EPRS Fee | L5: Allocation | S5: 1 | T5: 2 | U5: 3 | V5: 4 | W5: 5
S6: =IF(OR(Summary="Favorable",Summary="Unfavorable"),IF(IFERROR(VLOOKUP(INDEX([1]STRTG!$D$68:$D$321,MATCH(S$5,[1]STRTG!$C$68:$C$321,0),1),[1]STRTG!$N$14:$Q$303,4,FALSE),"")<>'Inputs & Summary'!$R$7,"",IFERROR(VLOOKUP(INDEX([1]STRTG!$D$68:$D$321,MATCH(S$5,[1]STRTG!$C$68:$C$321,0),1),[1]STRTG!$N$14:$Q$303,4,FALSE),"")),IFERROR(VLOOKUP(INDEX([1]STRTG!$D$68:$D$321,MATCH(S$5,[1]STRTG!$C$68:$C$321,0),1),[1]STRTG!$N$14:$Q$303,4,FALSE),"")) -> GSPC | T6: =IF(OR(Summary="Favorable",Summary="Unfavorable"),IF(IFERROR(VLOOKUP(INDEX([1]STRTG!$D$68:$D$321,MATCH(T$5,[1]STRTG!$C$68:$C$321,0),1),[1]STRTG!$N$14:$Q$303,4,FALSE),"")<>'Inputs & Summary'!$R$7,"",IFERROR(VLOOKUP(INDEX([1]STRTG!$D$68:$D$321,MATCH(T$5,[1]STRTG!$C$68:$C$321,0),1),[1]STRTG!$N$14:$Q$303,4,FALSE),"")),IFERROR(VLOOKUP(INDEX([1]STRTG!$D$68:$D$321,MATCH(T$5,[1]STRTG!$C$68:$C$321,0),1),[1]STRTG!$N$14:$Q$303,4,FALSE),"")) -> PIMGOPT | U6: =IF(OR(Summary="Favorable",Summary="Unfavorable"),IF(IFERROR(VLOOKUP(INDEX([1]STRTG!$D$68:$D$321,MATCH(U$5,[1]STRTG!$C$68:$C$321,0),1),[1]STRTG!$N$14:$Q$303,4,FALSE),"")<>'Inputs & Summary'!$R$7,"",IFERROR(VLOOKUP(INDEX([1]STRTG!$D$68:$D$321,MATCH(U$5,[1]STRTG!$C$68:$C$321,0),1),[1]STRTG!$N$14:$Q$303,4,FALSE),"")),IFERROR(VLOOKUP(INDEX([1]STRTG!$D$68:$D$321,MATCH(U$5,[1]STRTG!$C$68:$C$321,0),1),[1]STRTG!$N$14:$Q$303,4,FALSE),"")) -> MLSB | V6: =IF(OR(Summary="Favorable",Summary="Unfavorable"),IF(IFERROR(VLOOKUP(INDEX([1]STRTG!$D$68:$D$321,MATCH(V$5,[1]STRTG!$C$68:$C$321,0),1),[1]STRTG!$N$14:$Q$303,4,FALSE),"")<>'Inputs & Summary'!$R$7,"",IFERROR(VLOOKUP(INDEX([1]STRTG!$D$68:$D$321,MATCH(V$5,[1]STRTG!$C$68:$C$321,0),1),[1]STRTG!$N$14:$Q$303,4,FALSE),"")),IFERROR(VLOOKUP(INDEX([1]STRTG!$D$68:$D$321,MATCH(V$5,[1]STRTG!$C$68:$C$321,0),1),[1]STRTG!$N$14:$Q$303,4,FALSE),"")) | W6: =IF(OR(Summary="Favorable",Summary="Unfavorable"),IF(IFERROR(VLOOKUP(INDEX([1]STRTG!$D$68:$D$321,MATCH(W$5,[1]STRTG!$C$68:$C$321,0),1),[1]STRTG!$N$14:$Q$303,4,FALSE),"")<>'Inputs & Summary'!$R$7,"",IFERROR(VLOOKUP(INDEX([1]STRTG!$D$68:$D$321,MATCH(W$5,[1]STRTG!$C$68:$C$321,0),1),[1]STRTG!$N$14:$Q$303,4,FALSE),"")),IFERROR(VLOOKUP(INDEX([1]STRTG!$D$68:$D$321,MATCH(W$5,[1]STRTG!$C$68:$C$321,0),1),[1]STRTG!$N$14:$Q$303,4,FALSE),""))
E7: =IF(OR('Inputs & Summary'!$C$141="N",COUNTIFS('Inputs & Summary'!$B$142:$B$171,"<>",'Inputs & Summary'!$C$142:$C$171,">0")<>COUNTIF('Inputs & Summary'!$C$142:$C$171,">0")),"!!! Review Strategy Allocations and Make Appropriate Adjustments !!!","Illustrated Interest Crediting Strategies") -> Illustrated Interest Crediting Strategies | F7: Fixed Rate | G7: Cap Rate | H7: Participation Rate | I7: Trigger Rate | J7: Spread | K7: EPRS Fee % | L7: Allocation
G8: Cap Rate
P9: Year | Q9: Year | R9: Age | S9: Tenor Selectors | X9: Hypothetical Values | AK9: Legacy
B10: Owner | C10: ='Inputs & Summary'!C32 -> Valued Client | E10: {=_xlfn.UNIQUE(_xlfn._xlws.FILTER('Inputs & Summary'!$B$142:$B$171,'Inputs & Summary'!$C$142:$C$171>0))} -> 1-Year Fixed Rate, Fixed Account | F10: =IF($E10="","",INDEX([1]STRTG!$T$14:$AC$303,MATCH($E10,[1]STRTG!$P$14:$P$303,0),MATCH(F$5,[1]STRTG!$T$13:$AC$13,0))) -> 0.045 | G10: =IF($E10="","",INDEX([1]STRTG!$T$14:$AC$303,MATCH($E10,[1]STRTG!$P$14:$P$303,0),MATCH(G$5,[1]STRTG!$T$13:$AC$13,0))) -> N/A | H10: =IF($E10="","",INDEX([1]STRTG!$T$14:$AC$303,MATCH($E10,[1]STRTG!$P$14:$P$303,0),MATCH(H$5,[1]STRTG!$T$13:$AC$13,0))) -> N/A | I10: =IF($E10="","",INDEX([1]STRTG!$T$14:$AC$303,MATCH($E10,[1]STRTG!$P$14:$P$303,0),MATCH(I$5,[1]STRTG!$T$13:$AC$13,0))) -> N/A | J10: =IF($E10="","",INDEX([1]STRTG!$T$14:$AC$303,MATCH($E10,[1]STRTG!$P$14:$P$303,0),MATCH(J$5,[1]STRTG!$T$13:$AC$13,0))) -> N/A | K10: =IF($E10="","",IF(RIGHT(VLOOKUP($E10,[1]STRTG!$P$14:$S$303,4,FALSE),6)="EPRST1",Ref!$C$103,IF(RIGHT(VLOOKUP($E10,[1]STRTG!$P$14:$S$303,4,FALSE),6)="EPRST2",Ref!$C$104,"N/A"))) -> N/A | L10: =IF($E10="","",INDEX([1]STRTG!$T$14:$AC$303,MATCH($E10,[1]STRTG!$P$14:$P$303,0),MATCH(L$5,[1]STRTG!$T$13:$AC$13,0))) -> 0.1 | S10: 1-Year | T10: 1-Year | U10: 1-Year | V10: 1-Year | W10: 1-Year
B11: Election | C11: =Election -> Single Life | E11: 1-Year PTP with Secure Cap, S&P 500 | F11: =IF($E11="","",INDEX([1]STRTG!$T$14:$AC$303,MATCH($E11,[1]STRTG!$P$14:$P$303,0),MATCH(F$5,[1]STRTG!$T$13:$AC$13,0))) -> N/A | G11: =IF($E11="","",INDEX([1]STRTG!$T$14:$AC$303,MATCH($E11,[1]STRTG!$P$14:$P$303,0),MATCH(G$5,[1]STRTG!$T$13:$AC$13,0))) -> 0 | H11: =IF($E11="","",INDEX([1]STRTG!$T$14:$AC$303,MATCH($E11,[1]STRTG!$P$14:$P$303,0),MATCH(H$5,[1]STRTG!$T$13:$AC$13,0))) -> N/A | I11: =IF($E11="","",INDEX([1]STRTG!$T$14:$AC$303,MATCH($E11,[1]STRTG!$P$14:$P$303,0),MATCH(I$5,[1]STRTG!$T$13:$AC$13,0))) -> N/A | J11: =IF($E11="","",INDEX([1]STRTG!$T$14:$AC$303,MATCH($E11,[1]STRTG!$P$14:$P$303,0),MATCH(J$5,[1]STRTG!$T$13:$AC$13,0))) -> N/A | K11: =IF($E11="","",IF(RIGHT(VLOOKUP($E11,[1]STRTG!$P$14:$S$303,4,FALSE),6)="EPRST1",Ref!$C$103,IF(RIGHT(VLOOKUP($E11,[1]STRTG!$P$14:$S$303,4,FALSE),6)="EPRST2",Ref!$C$104,"N/A"))) -> N/A | L11: =IF($E11="","",INDEX([1]STRTG!$T$14:$AC$303,MATCH($E11,[1]STRTG!$P$14:$P$303,0),MATCH(L$5,[1]STRTG!$T$13:$AC$13,0))) -> 0.4 | S11: =IF(S$6="","",IF(INDEX([1]Allocated!$D$11:$AY$11,1,MATCH(S$5,[1]Allocated!$D$13:$AY$13,0))="","",INDEX([1]Allocated!$D$11:$AY$11,1,MATCH(S$5,[1]Allocated!$D$13:$AY$13,0))&" "&VLOOKUP(S$10,Ref!$Y$61:$AA$63,3,FALSE))) -> S&P 500 Index Annual Change | T11: =IF(T$6="","",IF(INDEX([1]Allocated!$D$11:$AY$11,1,MATCH(T$5,[1]Allocated!$D$13:$AY$13,0))="","",INDEX([1]Allocated!$D$11:$AY$11,1,MATCH(T$5,[1]Allocated!$D$13:$AY$13,0))&" "&VLOOKUP(T$10,Ref!$Y$61:$AA$63,3,FALSE))) -> PIMCO Global Optima Index Annual Change | U11: =IF(U$6="","",IF(INDEX([1]Allocated!$D$11:$AY$11,1,MATCH(U$5,[1]Allocated!$D$13:$AY$13,0))="","",INDEX([1]Allocated!$D$11:$AY$11,1,MATCH(U$5,[1]Allocated!$D$13:$AY$13,0))&" "&VLOOKUP(U$10,Ref!$Y$61:$AA$63,3,FALSE))) -> MLSB Index Annual Change | V11: =IF(V$6="","",IF(INDEX([1]Allocated!$D$11:$AY$11,1,MATCH(V$5,[1]Allocated!$D$13:$AY$13,0))="","",INDEX([1]Allocated!$D$11:$AY$11,1,MATCH(V$5,[1]Allocated!$D$13:$AY$13,0))&" "&VLOOKUP(V$10,Ref!$Y$61:$AA$63,3,FALSE))) | W11: =IF(W$6="","",IF(INDEX([1]Allocated!$D$11:$AY$11,1,MATCH(W$5,[1]Allocated!$D$13:$AY$13,0))="","",INDEX([1]Allocated!$D$11:$AY$11,1,MATCH(W$5,[1]Allocated!$D$13:$AY$13,0))&" "&VLOOKUP(W$10,Ref!$Y$61:$AA$63,3,FALSE))) | X11: Credited Interest Rate | Y11: =IF(OR(PTab="P7",AND(PTab="P2",Ref!$S$53="Y")),"Interest Earned including","Interest Earned") -> Interest Earned including | Z11: =IF(AND(LivBen<>"None",RIGHT(Category,2)<>"NY"),"Income Base","") | AA11: =IF(AND(LivBen<>"None",RIGHT(Category,2)<>"NY"),"Income Credit","") | AB11: =IF(AND(LivBen<>"None",RIGHT(Category,2)<>"NY"),"Annual Income for Life",IF(AND(LivBen<>"None",RIGHT(Category,2)="NY"),"Guaranteed Lifetime Income Amount","")) | AC11: Withdrawal Amount | AD11: Cumulative Withdrawals | AE11: Fees | AF11: Contract Anniversary Value | AG11: Cash Surrender Value | AH11: =IF(RIGHT(Category,2)="NY","Minimum Accumulation Value","Minimum Withdrawal Value") -> Minimum Withdrawal Value | AI11: =IF(PTab="P7","GROP Amount",IF(Ref!$S$53="Y","GMAB Value","")) -> GMAB Value | AJ11: =IF(PTab="P7","Overlay Credit",IF(Ref!$S$53="Y","GMAB Amount","")) -> GMAB Amount | AK11: Hypothetical Death Benefit
B12: Issue Age Original Annuitant | C12: =IssAge1 -> 73 | E12: 1-Year PTP with Cap, PIMCO Global Optima | F12: =IF($E12="","",INDEX([1]STRTG!$T$14:$AC$303,MATCH($E12,[1]STRTG!$P$14:$P$303,0),MATCH(F$5,[1]STRTG!$T$13:$AC$13,0))) -> N/A | G12: =IF($E12="","",INDEX([1]STRTG!$T$14:$AC$303,MATCH($E12,[1]STRTG!$P$14:$P$303,0),MATCH(G$5,[1]STRTG!$T$13:$AC$13,0))) -> 0.115 | H12: =IF($E12="","",INDEX([1]STRTG!$T$14:$AC$303,MATCH($E12,[1]STRTG!$P$14:$P$303,0),MATCH(H$5,[1]STRTG!$T$13:$AC$13,0))) -> N/A | I12: =IF($E12="","",INDEX([1]STRTG!$T$14:$AC$303,MATCH($E12,[1]STRTG!$P$14:$P$303,0),MATCH(I$5,[1]STRTG!$T$13:$AC$13,0))) -> N/A | J12: =IF($E12="","",INDEX([1]STRTG!$T$14:$AC$303,MATCH($E12,[1]STRTG!$P$14:$P$303,0),MATCH(J$5,[1]STRTG!$T$13:$AC$13,0))) -> N/A | K12: =IF($E12="","",IF(RIGHT(VLOOKUP($E12,[1]STRTG!$P$14:$S$303,4,FALSE),6)="EPRST1",Ref!$C$103,IF(RIGHT(VLOOKUP($E12,[1]STRTG!$P$14:$S$303,4,FALSE),6)="EPRST2",Ref!$C$104,"N/A"))) -> N/A | L12: =IF($E12="","",INDEX([1]STRTG!$T$14:$AC$303,MATCH($E12,[1]STRTG!$P$14:$P$303,0),MATCH(L$5,[1]STRTG!$T$13:$AC$13,0))) -> 0.1 | Y12: ='Inputs & Summary'!T10 -> #REF!
B13: Issue Age Second Annuitant if Joint | C13: =IF(Election = "Joint Life",IssAge2,"N/A") -> N/A | E13: 1-Year PTP with ParRate, MLSB | F13: =IF($E13="","",INDEX([1]STRTG!$T$14:$AC$303,MATCH($E13,[1]STRTG!$P$14:$P$303,0),MATCH(F$5,[1]STRTG!$T$13:$AC$13,0))) -> N/A | G13: =IF($E13="","",INDEX([1]STRTG!$T$14:$AC$303,MATCH($E13,[1]STRTG!$P$14:$P$303,0),MATCH(G$5,[1]STRTG!$T$13:$AC$13,0))) -> N/A | H13: =IF($E13="","",INDEX([1]STRTG!$T$14:$AC$303,MATCH($E13,[1]STRTG!$P$14:$P$303,0),MATCH(H$5,[1]STRTG!$T$13:$AC$13,0))) -> 0.97 | I13: =IF($E13="","",INDEX([1]STRTG!$T$14:$AC$303,MATCH($E13,[1]STRTG!$P$14:$P$303,0),MATCH(I$5,[1]STRTG!$T$13:$AC$13,0))) -> N/A | J13: =IF($E13="","",INDEX([1]STRTG!$T$14:$AC$303,MATCH($E13,[1]STRTG!$P$14:$P$303,0),MATCH(J$5,[1]STRTG!$T$13:$AC$13,0))) -> N/A | K13: =IF($E13="","",IF(RIGHT(VLOOKUP($E13,[1]STRTG!$P$14:$S$303,4,FALSE),6)="EPRST1",Ref!$C$103,IF(RIGHT(VLOOKUP($E13,[1]STRTG!$P$14:$S$303,4,FALSE),6)="EPRST2",Ref!$C$104,"N/A"))) -> N/A | L13: =IF($E13="","",INDEX([1]STRTG!$T$14:$AC$303,MATCH($E13,[1]STRTG!$P$14:$P$303,0),MATCH(L$5,[1]STRTG!$T$13:$AC$13,0))) -> 0.4 | P13: =IF('Inputs & Summary'!O11="","",IF('Inputs & Summary'!O11=0,"At Issue",'Inputs & Summary'!P11)) -> At Issue | Q13: =IF($P13="","",'Inputs & Summary'!O11) -> 0 | R13: =IF($P13="","",'Inputs & Summary'!Q11) -> #REF! | S13: {=IF($P13="","",IF(S$11="",0,IFERROR(INDEX(INDIRECT(S$6&VLOOKUP(Summary,Ref!$Y$13:$AC$18,3,FALSE)),MATCH(IF($P13="At Issue",VLOOKUP(Summary,Ref!$Y$13:$AC$18,2,FALSE),$P13),INDIRECT(S$6&VLOOKUP(Summary,Ref!$Y$13:$AC$18,4,FALSE)),0),VLOOKUP(S$10,Ref!$Y$61:$AA$63,2,FALSE)),0)))} -> 0 | T13: {=IF($P13="","",IF(T$11="",0,IFERROR(INDEX(INDIRECT(T$6&VLOOKUP(Summary,Ref!$Y$13:$AC$18,3,FALSE)),MATCH(IF($P13="At Issue",VLOOKUP(Summary,Ref!$Y$13:$AC$18,2,FALSE),$P13),INDIRECT(T$6&VLOOKUP(Summary,Ref!$Y$13:$AC$18,4,FALSE)),0),VLOOKUP(T$10,Ref!$Y$61:$AA$63,2,FALSE)),0)))} -> 0 | U13: {=IF($P13="","",IF(U$11="",0,IFERROR(INDEX(INDIRECT(U$6&VLOOKUP(Summary,Ref!$Y$13:$AC$18,3,FALSE)),MATCH(IF($P13="At Issue",VLOOKUP(Summary,Ref!$Y$13:$AC$18,2,FALSE),$P13),INDIRECT(U$6&VLOOKUP(Summary,Ref!$Y$13:$AC$18,4,FALSE)),0),VLOOKUP(U$10,Ref!$Y$61:$AA$63,2,FALSE)),0)))} -> 0 | V13: {=IF($P13="","",IF(V$11="",0,IFERROR(INDEX(INDIRECT(V$6&VLOOKUP(Summary,Ref!$Y$13:$AC$18,3,FALSE)),MATCH(IF($P13="At Issue",VLOOKUP(Summary,Ref!$Y$13:$AC$18,2,FALSE),$P13),INDIRECT(V$6&VLOOKUP(Summary,Ref!$Y$13:$AC$18,4,FALSE)),0),VLOOKUP(V$10,Ref!$Y$61:$AA$63,2,FALSE)),0)))} -> 0 | W13: {=IF($P13="","",IF(W$11="",0,IFERROR(INDEX(INDIRECT(W$6&VLOOKUP(Summary,Ref!$Y$13:$AC$18,3,FALSE)),MATCH(IF($P13="At Issue",VLOOKUP(Summary,Ref!$Y$13:$AC$18,2,FALSE),$P13),INDIRECT(W$6&VLOOKUP(Summary,Ref!$Y$13:$AC$18,4,FALSE)),0),VLOOKUP(W$10,Ref!$Y$61:$AA$63,2,FALSE)),0)))} -> 0 | X13: =IF($P13="","",'Inputs & Summary'!S11) -> #REF! | Y13: =IF($P13="","",'Inputs & Summary'!T11) -> #REF! | Z13: =IF($P13="","",IF($Z$11="",0,'Inputs & Summary'!X11)) -> 0 | AA13: =IF($P13="","",IF($AA$11="",0,IF(AND(LivBen<>"None",RIGHT(Category,2)<>"NY"),'Inputs & Summary'!AH11,""))) -> 0 | AB13: =IF($P13="","",'Inputs & Summary'!Y11) -> #REF! | AC13: =IF($P13="","",IF(RIGHT(Category,2)="NY",'Inputs & Summary'!AH11,SUM('Inputs & Summary'!AB11,'Inputs & Summary'!AE11*('Inputs & Summary'!AD11="Yes"),'Inputs & Summary'!AG11))) -> 0 | AD13: =IF($P13="","",'Inputs & Summary'!AI11) -> 0 | AE13: =IF($P13="","",'Inputs & Summary'!Z11) -> 0 | AF13: =IF($P13="","",'Inputs & Summary'!U11) -> #REF! | AG13: =IF($P13="","",'Inputs & Summary'!V11) -> #REF! | AH13: =IF($P13="","",'Inputs & Summary'!W11) -> #REF! | AI13: =IF($P13="","",IF($AI$11="",0,'Inputs & Summary'!AM11)) -> #REF! | AJ13: =IF($P13="","",IF($AJ$11="",0,IF(PTab="P7",'Inputs & Summary'!AQ11,'Inputs & Summary'!AA11))) -> #REF! | AK13: =IF($P13="","",'Inputs & Summary'!AJ11) -> #REF!
B14: Solicitation State | C14: =IF(RIGHT(Product,2)="NY",'Inputs & Summary'!$C$37,State) -> KS | F14: =IF($E14="","",INDEX([1]STRTG!$T$14:$AC$303,MATCH($E14,[1]STRTG!$P$14:$P$303,0),MATCH(F$5,[1]STRTG!$T$13:$AC$13,0))) | G14: =IF($E14="","",INDEX([1]STRTG!$T$14:$AC$303,MATCH($E14,[1]STRTG!$P$14:$P$303,0),MATCH(G$5,[1]STRTG!$T$13:$AC$13,0))) | H14: =IF($E14="","",INDEX([1]STRTG!$T$14:$AC$303,MATCH($E14,[1]STRTG!$P$14:$P$303,0),MATCH(H$5,[1]STRTG!$T$13:$AC$13,0))) | I14: =IF($E14="","",INDEX([1]STRTG!$T$14:$AC$303,MATCH($E14,[1]STRTG!$P$14:$P$303,0),MATCH(I$5,[1]STRTG!$T$13:$AC$13,0))) | J14: =IF($E14="","",INDEX([1]STRTG!$T$14:$AC$303,MATCH($E14,[1]STRTG!$P$14:$P$303,0),MATCH(J$5,[1]STRTG!$T$13:$AC$13,0))) | K14: =IF($E14="","",IF(RIGHT(VLOOKUP($E14,[1]STRTG!$P$14:$S$303,4,FALSE),6)="EPRST1",Ref!$C$103,IF(RIGHT(VLOOKUP($E14,[1]STRTG!$P$14:$S$303,4,FALSE),6)="EPRST2",Ref!$C$104,"N/A"))) | L14: =IF($E14="","",INDEX([1]STRTG!$T$14:$AC$303,MATCH($E14,[1]STRTG!$P$14:$P$303,0),MATCH(L$5,[1]STRTG!$T$13:$AC$13,0))) | P14: =IF('Inputs & Summary'!O12="","",IF('Inputs & Summary'!O12=0,"At Issue",'Inputs & Summary'!P12)) -> #REF! | Q14: =IF($P14="","",'Inputs & Summary'!O12) -> #REF! | R14: =IF($P14="","",'Inputs & Summary'!Q12) -> #REF! | S14: {=IF($P14="","",IF(S$11="",0,IFERROR(INDEX(INDIRECT(S$6&VLOOKUP(Summary,Ref!$Y$13:$AC$18,3,FALSE)),MATCH(IF($P14="At Issue",VLOOKUP(Summary,Ref!$Y$13:$AC$18,2,FALSE),$P14),INDIRECT(S$6&VLOOKUP(Summary,Ref!$Y$13:$AC$18,4,FALSE)),0),VLOOKUP(S$10,Ref!$Y$61:$AA$63,2,FALSE)),0)))} -> #REF! | T14: {=IF($P14="","",IF(T$11="",0,IFERROR(INDEX(INDIRECT(T$6&VLOOKUP(Summary,Ref!$Y$13:$AC$18,3,FALSE)),MATCH(IF($P14="At Issue",VLOOKUP(Summary,Ref!$Y$13:$AC$18,2,FALSE),$P14),INDIRECT(T$6&VLOOKUP(Summary,Ref!$Y$13:$AC$18,4,FALSE)),0),VLOOKUP(T$10,Ref!$Y$61:$AA$63,2,FALSE)),0)))} -> #REF! | U14: {=IF($P14="","",IF(U$11="",0,IFERROR(INDEX(INDIRECT(U$6&VLOOKUP(Summary,Ref!$Y$13:$AC$18,3,FALSE)),MATCH(IF($P14="At Issue",VLOOKUP(Summary,Ref!$Y$13:$AC$18,2,FALSE),$P14),INDIRECT(U$6&VLOOKUP(Summary,Ref!$Y$13:$AC$18,4,FALSE)),0),VLOOKUP(U$10,Ref!$Y$61:$AA$63,2,FALSE)),0)))} -> #REF! | V14: {=IF($P14="","",IF(V$11="",0,IFERROR(INDEX(INDIRECT(V$6&VLOOKUP(Summary,Ref!$Y$13:$AC$18,3,FALSE)),MATCH(IF($P14="At Issue",VLOOKUP(Summary,Ref!$Y$13:$AC$18,2,FALSE),$P14),INDIRECT(V$6&VLOOKUP(Summary,Ref!$Y$13:$AC$18,4,FALSE)),0),VLOOKUP(V$10,Ref!$Y$61:$AA$63,2,FALSE)),0)))} -> #REF! | W14: {=IF($P14="","",IF(W$11="",0,IFERROR(INDEX(INDIRECT(W$6&VLOOKUP(Summary,Ref!$Y$13:$AC$18,3,FALSE)),MATCH(IF($P14="At Issue",VLOOKUP(Summary,Ref!$Y$13:$AC$18,2,FALSE),$P14),INDIRECT(W$6&VLOOKUP(Summary,Ref!$Y$13:$AC$18,4,FALSE)),0),VLOOKUP(W$10,Ref!$Y$61:$AA$63,2,FALSE)),0)))} -> #REF! | X14: =IF($P14="","",'Inputs & Summary'!S12) -> #REF! | Y14: =IF($P14="","",'Inputs & Summary'!T12) -> #REF! | Z14: =IF($P14="","",IF($Z$11="",0,'Inputs & Summary'!X12)) -> #REF! | AA14: =IF($P14="","",IF($AA$11="",0,IF(AND(LivBen<>"None",RIGHT(Category,2)<>"NY"),'Inputs & Summary'!AH12,""))) -> #REF! | AB14: =IF($P14="","",'Inputs & Summary'!Y12) -> #REF! | AC14: =IF($P14="","",IF(RIGHT(Category,2)="NY",'Inputs & Summary'!AH12,SUM('Inputs & Summary'!AB12,'Inputs & Summary'!AE12*('Inputs & Summary'!AD12="Yes"),'Inputs & Summary'!AG12))) -> #REF! | AD14: =IF($P14="","",'Inputs & Summary'!AI12) -> #REF! | AE14: =IF($P14="","",'Inputs & Summary'!Z12) -> #REF! | AF14: =IF($P14="","",'Inputs & Summary'!U12) -> #REF! | AG14: =IF($P14="","",'Inputs & Summary'!V12) -> #REF! | AH14: =IF($P14="","",'Inputs & Summary'!W12) -> #REF! | AI14: =IF($P14="","",IF($AI$11="",0,'Inputs & Summary'!AM12)) -> #REF! | AJ14: =IF($P14="","",IF($AJ$11="",0,IF(PTab="P7",'Inputs & Summary'!AQ12,'Inputs & Summary'!AA12))) -> #REF! | AK14: =IF($P14="","",'Inputs & Summary'!AJ12) -> #REF!
B15: Contract Type | C15: ='Inputs & Summary'!C39 -> Qualified | F15: =IF($E15="","",INDEX([1]STRTG!$T$14:$AC$303,MATCH($E15,[1]STRTG!$P$14:$P$303,0),MATCH(F$5,[1]STRTG!$T$13:$AC$13,0))) | G15: =IF($E15="","",INDEX([1]STRTG!$T$14:$AC$303,MATCH($E15,[1]STRTG!$P$14:$P$303,0),MATCH(G$5,[1]STRTG!$T$13:$AC$13,0))) | H15: =IF($E15="","",INDEX([1]STRTG!$T$14:$AC$303,MATCH($E15,[1]STRTG!$P$14:$P$303,0),MATCH(H$5,[1]STRTG!$T$13:$AC$13,0))) | I15: =IF($E15="","",INDEX([1]STRTG!$T$14:$AC$303,MATCH($E15,[1]STRTG!$P$14:$P$303,0),MATCH(I$5,[1]STRTG!$T$13:$AC$13,0))) | J15: =IF($E15="","",INDEX([1]STRTG!$T$14:$AC$303,MATCH($E15,[1]STRTG!$P$14:$P$303,0),MATCH(J$5,[1]STRTG!$T$13:$AC$13,0))) | K15: =IF($E15="","",IF(RIGHT(VLOOKUP($E15,[1]STRTG!$P$14:$S$303,4,FALSE),6)="EPRST1",Ref!$C$103,IF(RIGHT(VLOOKUP($E15,[1]STRTG!$P$14:$S$303,4,FALSE),6)="EPRST2",Ref!$C$104,"N/A"))) | L15: =IF($E15="","",INDEX([1]STRTG!$T$14:$AC$303,MATCH($E15,[1]STRTG!$P$14:$P$303,0),MATCH(L$5,[1]STRTG!$T$13:$AC$13,0))) | P15: =IF('Inputs & Summary'!O13="","",IF('Inputs & Summary'!O13=0,"At Issue",'Inputs & Summary'!P13)) -> #REF! | Q15: =IF($P15="","",'Inputs & Summary'!O13) -> #REF! | R15: =IF($P15="","",'Inputs & Summary'!Q13) -> #REF! | S15: {=IF($P15="","",IF(S$11="",0,IFERROR(INDEX(INDIRECT(S$6&VLOOKUP(Summary,Ref!$Y$13:$AC$18,3,FALSE)),MATCH(IF($P15="At Issue",VLOOKUP(Summary,Ref!$Y$13:$AC$18,2,FALSE),$P15),INDIRECT(S$6&VLOOKUP(Summary,Ref!$Y$13:$AC$18,4,FALSE)),0),VLOOKUP(S$10,Ref!$Y$61:$AA$63,2,FALSE)),0)))} -> #REF! | T15: {=IF($P15="","",IF(T$11="",0,IFERROR(INDEX(INDIRECT(T$6&VLOOKUP(Summary,Ref!$Y$13:$AC$18,3,FALSE)),MATCH(IF($P15="At Issue",VLOOKUP(Summary,Ref!$Y$13:$AC$18,2,FALSE),$P15),INDIRECT(T$6&VLOOKUP(Summary,Ref!$Y$13:$AC$18,4,FALSE)),0),VLOOKUP(T$10,Ref!$Y$61:$AA$63,2,FALSE)),0)))} -> #REF! | U15: {=IF($P15="","",IF(U$11="",0,IFERROR(INDEX(INDIRECT(U$6&VLOOKUP(Summary,Ref!$Y$13:$AC$18,3,FALSE)),MATCH(IF($P15="At Issue",VLOOKUP(Summary,Ref!$Y$13:$AC$18,2,FALSE),$P15),INDIRECT(U$6&VLOOKUP(Summary,Ref!$Y$13:$AC$18,4,FALSE)),0),VLOOKUP(U$10,Ref!$Y$61:$AA$63,2,FALSE)),0)))} -> #REF! | V15: {=IF($P15="","",IF(V$11="",0,IFERROR(INDEX(INDIRECT(V$6&VLOOKUP(Summary,Ref!$Y$13:$AC$18,3,FALSE)),MATCH(IF($P15="At Issue",VLOOKUP(Summary,Ref!$Y$13:$AC$18,2,FALSE),$P15),INDIRECT(V$6&VLOOKUP(Summary,Ref!$Y$13:$AC$18,4,FALSE)),0),VLOOKUP(V$10,Ref!$Y$61:$AA$63,2,FALSE)),0)))} -> #REF! | W15: {=IF($P15="","",IF(W$11="",0,IFERROR(INDEX(INDIRECT(W$6&VLOOKUP(Summary,Ref!$Y$13:$AC$18,3,FALSE)),MATCH(IF($P15="At Issue",VLOOKUP(Summary,Ref!$Y$13:$AC$18,2,FALSE),$P15),INDIRECT(W$6&VLOOKUP(Summary,Ref!$Y$13:$AC$18,4,FALSE)),0),VLOOKUP(W$10,Ref!$Y$61:$AA$63,2,FALSE)),0)))} -> #REF! | X15: =IF($P15="","",'Inputs & Summary'!S13) -> #REF! | Y15: =IF($P15="","",'Inputs & Summary'!T13) -> #REF! | Z15: =IF($P15="","",IF($Z$11="",0,'Inputs & Summary'!X13)) -> #REF! | AA15: =IF($P15="","",IF($AA$11="",0,IF(AND(LivBen<>"None",RIGHT(Category,2)<>"NY"),'Inputs & Summary'!AH13,""))) -> #REF! | AB15: =IF($P15="","",'Inputs & Summary'!Y13) -> #REF! | AC15: =IF($P15="","",IF(RIGHT(Category,2)="NY",'Inputs & Summary'!AH13,SUM('Inputs & Summary'!AB13,'Inputs & Summary'!AE13*('Inputs & Summary'!AD13="Yes"),'Inputs & Summary'!AG13))) -> #REF! | AD15: =IF($P15="","",'Inputs & Summary'!AI13) -> #REF! | AE15: =IF($P15="","",'Inputs & Summary'!Z13) -> #REF! | AF15: =IF($P15="","",'Inputs & Summary'!U13) -> #REF! | AG15: =IF($P15="","",'Inputs & Summary'!V13) -> #REF! | AH15: =IF($P15="","",'Inputs & Summary'!W13) -> #REF! | AI15: =IF($P15="","",IF($AI$11="",0,'Inputs & Summary'!AM13)) -> #REF! | AJ15: =IF($P15="","",IF($AJ$11="",0,IF(PTab="P7",'Inputs & Summary'!AQ13,'Inputs & Summary'!AA13))) -> #REF! | AK15: =IF($P15="","",'Inputs & Summary'!AJ13) -> #REF!
B16: Product | C16: =Product -> Power Index Plus | F16: =IF($E16="","",INDEX([1]STRTG!$T$14:$AC$303,MATCH($E16,[1]STRTG!$P$14:$P$303,0),MATCH(F$5,[1]STRTG!$T$13:$AC$13,0))) | G16: =IF($E16="","",INDEX([1]STRTG!$T$14:$AC$303,MATCH($E16,[1]STRTG!$P$14:$P$303,0),MATCH(G$5,[1]STRTG!$T$13:$AC$13,0))) | H16: =IF($E16="","",INDEX([1]STRTG!$T$14:$AC$303,MATCH($E16,[1]STRTG!$P$14:$P$303,0),MATCH(H$5,[1]STRTG!$T$13:$AC$13,0))) | I16: =IF($E16="","",INDEX([1]STRTG!$T$14:$AC$303,MATCH($E16,[1]STRTG!$P$14:$P$303,0),MATCH(I$5,[1]STRTG!$T$13:$AC$13,0))) | J16: =IF($E16="","",INDEX([1]STRTG!$T$14:$AC$303,MATCH($E16,[1]STRTG!$P$14:$P$303,0),MATCH(J$5,[1]STRTG!$T$13:$AC$13,0))) | K16: =IF($E16="","",IF(RIGHT(VLOOKUP($E16,[1]STRTG!$P$14:$S$303,4,FALSE),6)="EPRST1",Ref!$C$103,IF(RIGHT(VLOOKUP($E16,[1]STRTG!$P$14:$S$303,4,FALSE),6)="EPRST2",Ref!$C$104,"N/A"))) | L16: =IF($E16="","",INDEX([1]STRTG!$T$14:$AC$303,MATCH($E16,[1]STRTG!$P$14:$P$303,0),MATCH(L$5,[1]STRTG!$T$13:$AC$13,0))) | P16: =IF('Inputs & Summary'!O14="","",IF('Inputs & Summary'!O14=0,"At Issue",'Inputs & Summary'!P14)) -> #REF! | Q16: =IF($P16="","",'Inputs & Summary'!O14) -> #REF! | R16: =IF($P16="","",'Inputs & Summary'!Q14) -> #REF! | S16: {=IF($P16="","",IF(S$11="",0,IFERROR(INDEX(INDIRECT(S$6&VLOOKUP(Summary,Ref!$Y$13:$AC$18,3,FALSE)),MATCH(IF($P16="At Issue",VLOOKUP(Summary,Ref!$Y$13:$AC$18,2,FALSE),$P16),INDIRECT(S$6&VLOOKUP(Summary,Ref!$Y$13:$AC$18,4,FALSE)),0),VLOOKUP(S$10,Ref!$Y$61:$AA$63,2,FALSE)),0)))} -> #REF! | T16: {=IF($P16="","",IF(T$11="",0,IFERROR(INDEX(INDIRECT(T$6&VLOOKUP(Summary,Ref!$Y$13:$AC$18,3,FALSE)),MATCH(IF($P16="At Issue",VLOOKUP(Summary,Ref!$Y$13:$AC$18,2,FALSE),$P16),INDIRECT(T$6&VLOOKUP(Summary,Ref!$Y$13:$AC$18,4,FALSE)),0),VLOOKUP(T$10,Ref!$Y$61:$AA$63,2,FALSE)),0)))} -> #REF! | U16: {=IF($P16="","",IF(U$11="",0,IFERROR(INDEX(INDIRECT(U$6&VLOOKUP(Summary,Ref!$Y$13:$AC$18,3,FALSE)),MATCH(IF($P16="At Issue",VLOOKUP(Summary,Ref!$Y$13:$AC$18,2,FALSE),$P16),INDIRECT(U$6&VLOOKUP(Summary,Ref!$Y$13:$AC$18,4,FALSE)),0),VLOOKUP(U$10,Ref!$Y$61:$AA$63,2,FALSE)),0)))} -> #REF! | V16: {=IF($P16="","",IF(V$11="",0,IFERROR(INDEX(INDIRECT(V$6&VLOOKUP(Summary,Ref!$Y$13:$AC$18,3,FALSE)),MATCH(IF($P16="At Issue",VLOOKUP(Summary,Ref!$Y$13:$AC$18,2,FALSE),$P16),INDIRECT(V$6&VLOOKUP(Summary,Ref!$Y$13:$AC$18,4,FALSE)),0),VLOOKUP(V$10,Ref!$Y$61:$AA$63,2,FALSE)),0)))} -> #REF! | W16: {=IF($P16="","",IF(W$11="",0,IFERROR(INDEX(INDIRECT(W$6&VLOOKUP(Summary,Ref!$Y$13:$AC$18,3,FALSE)),MATCH(IF($P16="At Issue",VLOOKUP(Summary,Ref!$Y$13:$AC$18,2,FALSE),$P16),INDIRECT(W$6&VLOOKUP(Summary,Ref!$Y$13:$AC$18,4,FALSE)),0),VLOOKUP(W$10,Ref!$Y$61:$AA$63,2,FALSE)),0)))} -> #REF! | X16: =IF($P16="","",'Inputs & Summary'!S14) -> #REF! | Y16: =IF($P16="","",'Inputs & Summary'!T14) -> #REF! | Z16: =IF($P16="","",IF($Z$11="",0,'Inputs & Summary'!X14)) -> #REF! | AA16: =IF($P16="","",IF($AA$11="",0,IF(AND(LivBen<>"None",RIGHT(Category,2)<>"NY"),'Inputs & Summary'!AH14,""))) -> #REF! | AB16: =IF($P16="","",'Inputs & Summary'!Y14) -> #REF! | AC16: =IF($P16="","",IF(RIGHT(Category,2)="NY",'Inputs & Summary'!AH14,SUM('Inputs & Summary'!AB14,'Inputs & Summary'!AE14*('Inputs & Summary'!AD14="Yes"),'Inputs & Summary'!AG14))) -> #REF! | AD16: =IF($P16="","",'Inputs & Summary'!AI14) -> #REF! | AE16: =IF($P16="","",'Inputs & Summary'!Z14) -> #REF! | AF16: =IF($P16="","",'Inputs & Summary'!U14) -> #REF! | AG16: =IF($P16="","",'Inputs & Summary'!V14) -> #REF! | AH16: =IF($P16="","",'Inputs & Summary'!W14) -> #REF! | AI16: =IF($P16="","",IF($AI$11="",0,'Inputs & Summary'!AM14)) -> #REF! | AJ16: =IF($P16="","",IF($AJ$11="",0,IF(PTab="P7",'Inputs & Summary'!AQ14,'Inputs & Summary'!AA14))) -> #REF! | AK16: =IF($P16="","",'Inputs & Summary'!AJ14) -> #REF!
B17: Initial Premium | C17: =InPrem -> 10000 | F17: =IF($E17="","",INDEX([1]STRTG!$T$14:$AC$303,MATCH($E17,[1]STRTG!$P$14:$P$303,0),MATCH(F$5,[1]STRTG!$T$13:$AC$13,0))) | G17: =IF($E17="","",INDEX([1]STRTG!$T$14:$AC$303,MATCH($E17,[1]STRTG!$P$14:$P$303,0),MATCH(G$5,[1]STRTG!$T$13:$AC$13,0))) | H17: =IF($E17="","",INDEX([1]STRTG!$T$14:$AC$303,MATCH($E17,[1]STRTG!$P$14:$P$303,0),MATCH(H$5,[1]STRTG!$T$13:$AC$13,0))) | I17: =IF($E17="","",INDEX([1]STRTG!$T$14:$AC$303,MATCH($E17,[1]STRTG!$P$14:$P$303,0),MATCH(I$5,[1]STRTG!$T$13:$AC$13,0))) | J17: =IF($E17="","",INDEX([1]STRTG!$T$14:$AC$303,MATCH($E17,[1]STRTG!$P$14:$P$303,0),MATCH(J$5,[1]STRTG!$T$13:$AC$13,0))) | K17: =IF($E17="","",IF(RIGHT(VLOOKUP($E17,[1]STRTG!$P$14:$S$303,4,FALSE),6)="EPRST1",Ref!$C$103,IF(RIGHT(VLOOKUP($E17,[1]STRTG!$P$14:$S$303,4,FALSE),6)="EPRST2",Ref!$C$104,"N/A"))) | L17: =IF($E17="","",INDEX([1]STRTG!$T$14:$AC$303,MATCH($E17,[1]STRTG!$P$14:$P$303,0),MATCH(L$5,[1]STRTG!$T$13:$AC$13,0))) | P17: =IF('Inputs & Summary'!O15="","",IF('Inputs & Summary'!O15=0,"At Issue",'Inputs & Summary'!P15)) -> #REF! | Q17: =IF($P17="","",'Inputs & Summary'!O15) -> #REF! | R17: =IF($P17="","",'Inputs & Summary'!Q15) -> #REF! | S17: {=IF($P17="","",IF(S$11="",0,IFERROR(INDEX(INDIRECT(S$6&VLOOKUP(Summary,Ref!$Y$13:$AC$18,3,FALSE)),MATCH(IF($P17="At Issue",VLOOKUP(Summary,Ref!$Y$13:$AC$18,2,FALSE),$P17),INDIRECT(S$6&VLOOKUP(Summary,Ref!$Y$13:$AC$18,4,FALSE)),0),VLOOKUP(S$10,Ref!$Y$61:$AA$63,2,FALSE)),0)))} -> #REF! | T17: {=IF($P17="","",IF(T$11="",0,IFERROR(INDEX(INDIRECT(T$6&VLOOKUP(Summary,Ref!$Y$13:$AC$18,3,FALSE)),MATCH(IF($P17="At Issue",VLOOKUP(Summary,Ref!$Y$13:$AC$18,2,FALSE),$P17),INDIRECT(T$6&VLOOKUP(Summary,Ref!$Y$13:$AC$18,4,FALSE)),0),VLOOKUP(T$10,Ref!$Y$61:$AA$63,2,FALSE)),0)))} -> #REF! | U17: {=IF($P17="","",IF(U$11="",0,IFERROR(INDEX(INDIRECT(U$6&VLOOKUP(Summary,Ref!$Y$13:$AC$18,3,FALSE)),MATCH(IF($P17="At Issue",VLOOKUP(Summary,Ref!$Y$13:$AC$18,2,FALSE),$P17),INDIRECT(U$6&VLOOKUP(Summary,Ref!$Y$13:$AC$18,4,FALSE)),0),VLOOKUP(U$10,Ref!$Y$61:$AA$63,2,FALSE)),0)))} -> #REF! | V17: {=IF($P17="","",IF(V$11="",0,IFERROR(INDEX(INDIRECT(V$6&VLOOKUP(Summary,Ref!$Y$13:$AC$18,3,FALSE)),MATCH(IF($P17="At Issue",VLOOKUP(Summary,Ref!$Y$13:$AC$18,2,FALSE),$P17),INDIRECT(V$6&VLOOKUP(Summary,Ref!$Y$13:$AC$18,4,FALSE)),0),VLOOKUP(V$10,Ref!$Y$61:$AA$63,2,FALSE)),0)))} -> #REF! | W17: {=IF($P17="","",IF(W$11="",0,IFERROR(INDEX(INDIRECT(W$6&VLOOKUP(Summary,Ref!$Y$13:$AC$18,3,FALSE)),MATCH(IF($P17="At Issue",VLOOKUP(Summary,Ref!$Y$13:$AC$18,2,FALSE),$P17),INDIRECT(W$6&VLOOKUP(Summary,Ref!$Y$13:$AC$18,4,FALSE)),0),VLOOKUP(W$10,Ref!$Y$61:$AA$63,2,FALSE)),0)))} -> #REF! | X17: =IF($P17="","",'Inputs & Summary'!S15) -> #REF! | Y17: =IF($P17="","",'Inputs & Summary'!T15) -> #REF! | Z17: =IF($P17="","",IF($Z$11="",0,'Inputs & Summary'!X15)) -> #REF! | AA17: =IF($P17="","",IF($AA$11="",0,IF(AND(LivBen<>"None",RIGHT(Category,2)<>"NY"),'Inputs & Summary'!AH15,""))) -> #REF! | AB17: =IF($P17="","",'Inputs & Summary'!Y15) -> #REF! | AC17: =IF($P17="","",IF(RIGHT(Category,2)="NY",'Inputs & Summary'!AH15,SUM('Inputs & Summary'!AB15,'Inputs & Summary'!AE15*('Inputs & Summary'!AD15="Yes"),'Inputs & Summary'!AG15))) -> #REF! | AD17: =IF($P17="","",'Inputs & Summary'!AI15) -> #REF! | AE17: =IF($P17="","",'Inputs & Summary'!Z15) -> #REF! | AF17: =IF($P17="","",'Inputs & Summary'!U15) -> #REF! | AG17: =IF($P17="","",'Inputs & Summary'!V15) -> #REF! | AH17: =IF($P17="","",'Inputs & Summary'!W15) -> #REF! | AI17: =IF($P17="","",IF($AI$11="",0,'Inputs & Summary'!AM15)) -> #REF! | AJ17: =IF($P17="","",IF($AJ$11="",0,IF(PTab="P7",'Inputs & Summary'!AQ15,'Inputs & Summary'!AA15))) -> #REF! | AK17: =IF($P17="","",'Inputs & Summary'!AJ15) -> #REF!
B18: Death Benefit | C18: =IF(PTab="P7","Return of Premium","Contract Value") -> Contract Value | F18: =IF($E18="","",INDEX([1]STRTG!$T$14:$AC$303,MATCH($E18,[1]STRTG!$P$14:$P$303,0),MATCH(F$5,[1]STRTG!$T$13:$AC$13,0))) | G18: =IF($E18="","",INDEX([1]STRTG!$T$14:$AC$303,MATCH($E18,[1]STRTG!$P$14:$P$303,0),MATCH(G$5,[1]STRTG!$T$13:$AC$13,0))) | H18: =IF($E18="","",INDEX([1]STRTG!$T$14:$AC$303,MATCH($E18,[1]STRTG!$P$14:$P$303,0),MATCH(H$5,[1]STRTG!$T$13:$AC$13,0))) | I18: =IF($E18="","",INDEX([1]STRTG!$T$14:$AC$303,MATCH($E18,[1]STRTG!$P$14:$P$303,0),MATCH(I$5,[1]STRTG!$T$13:$AC$13,0))) | J18: =IF($E18="","",INDEX([1]STRTG!$T$14:$AC$303,MATCH($E18,[1]STRTG!$P$14:$P$303,0),MATCH(J$5,[1]STRTG!$T$13:$AC$13,0))) | K18: =IF($E18="","",IF(RIGHT(VLOOKUP($E18,[1]STRTG!$P$14:$S$303,4,FALSE),6)="EPRST1",Ref!$C$103,IF(RIGHT(VLOOKUP($E18,[1]STRTG!$P$14:$S$303,4,FALSE),6)="EPRST2",Ref!$C$104,"N/A"))) | L18: =IF($E18="","",INDEX([1]STRTG!$T$14:$AC$303,MATCH($E18,[1]STRTG!$P$14:$P$303,0),MATCH(L$5,[1]STRTG!$T$13:$AC$13,0))) | P18: =IF('Inputs & Summary'!O16="","",IF('Inputs & Summary'!O16=0,"At Issue",'Inputs & Summary'!P16)) -> #REF! | Q18: =IF($P18="","",'Inputs & Summary'!O16) -> #REF! | R18: =IF($P18="","",'Inputs & Summary'!Q16) -> #REF! | S18: {=IF($P18="","",IF(S$11="",0,IFERROR(INDEX(INDIRECT(S$6&VLOOKUP(Summary,Ref!$Y$13:$AC$18,3,FALSE)),MATCH(IF($P18="At Issue",VLOOKUP(Summary,Ref!$Y$13:$AC$18,2,FALSE),$P18),INDIRECT(S$6&VLOOKUP(Summary,Ref!$Y$13:$AC$18,4,FALSE)),0),VLOOKUP(S$10,Ref!$Y$61:$AA$63,2,FALSE)),0)))} -> #REF! | T18: {=IF($P18="","",IF(T$11="",0,IFERROR(INDEX(INDIRECT(T$6&VLOOKUP(Summary,Ref!$Y$13:$AC$18,3,FALSE)),MATCH(IF($P18="At Issue",VLOOKUP(Summary,Ref!$Y$13:$AC$18,2,FALSE),$P18),INDIRECT(T$6&VLOOKUP(Summary,Ref!$Y$13:$AC$18,4,FALSE)),0),VLOOKUP(T$10,Ref!$Y$61:$AA$63,2,FALSE)),0)))} -> #REF! | U18: {=IF($P18="","",IF(U$11="",0,IFERROR(INDEX(INDIRECT(U$6&VLOOKUP(Summary,Ref!$Y$13:$AC$18,3,FALSE)),MATCH(IF($P18="At Issue",VLOOKUP(Summary,Ref!$Y$13:$AC$18,2,FALSE),$P18),INDIRECT(U$6&VLOOKUP(Summary,Ref!$Y$13:$AC$18,4,FALSE)),0),VLOOKUP(U$10,Ref!$Y$61:$AA$63,2,FALSE)),0)))} -> #REF! | V18: {=IF($P18="","",IF(V$11="",0,IFERROR(INDEX(INDIRECT(V$6&VLOOKUP(Summary,Ref!$Y$13:$AC$18,3,FALSE)),MATCH(IF($P18="At Issue",VLOOKUP(Summary,Ref!$Y$13:$AC$18,2,FALSE),$P18),INDIRECT(V$6&VLOOKUP(Summary,Ref!$Y$13:$AC$18,4,FALSE)),0),VLOOKUP(V$10,Ref!$Y$61:$AA$63,2,FALSE)),0)))} -> #REF! | W18: {=IF($P18="","",IF(W$11="",0,IFERROR(INDEX(INDIRECT(W$6&VLOOKUP(Summary,Ref!$Y$13:$AC$18,3,FALSE)),MATCH(IF($P18="At Issue",VLOOKUP(Summary,Ref!$Y$13:$AC$18,2,FALSE),$P18),INDIRECT(W$6&VLOOKUP(Summary,Ref!$Y$13:$AC$18,4,FALSE)),0),VLOOKUP(W$10,Ref!$Y$61:$AA$63,2,FALSE)),0)))} -> #REF! | X18: =IF($P18="","",'Inputs & Summary'!S16) -> #REF! | Y18: =IF($P18="","",'Inputs & Summary'!T16) -> #REF! | Z18: =IF($P18="","",IF($Z$11="",0,'Inputs & Summary'!X16)) -> #REF! | AA18: =IF($P18="","",IF($AA$11="",0,IF(AND(LivBen<>"None",RIGHT(Category,2)<>"NY"),'Inputs & Summary'!AH16,""))) -> #REF! | AB18: =IF($P18="","",'Inputs & Summary'!Y16) -> #REF! | AC18: =IF($P18="","",IF(RIGHT(Category,2)="NY",'Inputs & Summary'!AH16,SUM('Inputs & Summary'!AB16,'Inputs & Summary'!AE16*('Inputs & Summary'!AD16="Yes"),'Inputs & Summary'!AG16))) -> #REF! | AD18: =IF($P18="","",'Inputs & Summary'!AI16) -> #REF! | AE18: =IF($P18="","",'Inputs & Summary'!Z16) -> #REF! | AF18: =IF($P18="","",'Inputs & Summary'!U16) -> #REF! | AG18: =IF($P18="","",'Inputs & Summary'!V16) -> #REF! | AH18: =IF($P18="","",'Inputs & Summary'!W16) -> #REF! | AI18: =IF($P18="","",IF($AI$11="",0,'Inputs & Summary'!AM16)) -> #REF! | AJ18: =IF($P18="","",IF($AJ$11="",0,IF(PTab="P7",'Inputs & Summary'!AQ16,'Inputs & Summary'!AA16))) -> #REF! | AK18: =IF($P18="","",'Inputs & Summary'!AJ16) -> #REF!
B19: =IF(PTab="P7","AICO Product Fee",IF(Ref!$S$53="Y","GMAB Rate","")) -> GMAB Rate | C19: =IF(PTab="P7",AICOPrFee,IF(Ref!$S$53="Y",GMABR,"")) -> 0.05 | F19: =IF($E19="","",INDEX([1]STRTG!$T$14:$AC$303,MATCH($E19,[1]STRTG!$P$14:$P$303,0),MATCH(F$5,[1]STRTG!$T$13:$AC$13,0))) | G19: =IF($E19="","",INDEX([1]STRTG!$T$14:$AC$303,MATCH($E19,[1]STRTG!$P$14:$P$303,0),MATCH(G$5,[1]STRTG!$T$13:$AC$13,0))) | H19: =IF($E19="","",INDEX([1]STRTG!$T$14:$AC$303,MATCH($E19,[1]STRTG!$P$14:$P$303,0),MATCH(H$5,[1]STRTG!$T$13:$AC$13,0))) | I19: =IF($E19="","",INDEX([1]STRTG!$T$14:$AC$303,MATCH($E19,[1]STRTG!$P$14:$P$303,0),MATCH(I$5,[1]STRTG!$T$13:$AC$13,0))) | J19: =IF($E19="","",INDEX([1]STRTG!$T$14:$AC$303,MATCH($E19,[1]STRTG!$P$14:$P$303,0),MATCH(J$5,[1]STRTG!$T$13:$AC$13,0))) | K19: =IF($E19="","",IF(RIGHT(VLOOKUP($E19,[1]STRTG!$P$14:$S$303,4,FALSE),6)="EPRST1",Ref!$C$103,IF(RIGHT(VLOOKUP($E19,[1]STRTG!$P$14:$S$303,4,FALSE),6)="EPRST2",Ref!$C$104,"N/A"))) | L19: =IF($E19="","",INDEX([1]STRTG!$T$14:$AC$303,MATCH($E19,[1]STRTG!$P$14:$P$303,0),MATCH(L$5,[1]STRTG!$T$13:$AC$13,0))) | P19: =IF('Inputs & Summary'!O17="","",IF('Inputs & Summary'!O17=0,"At Issue",'Inputs & Summary'!P17)) -> #REF! | Q19: =IF($P19="","",'Inputs & Summary'!O17) -> #REF! | R19: =IF($P19="","",'Inputs & Summary'!Q17) -> #REF! | S19: {=IF($P19="","",IF(S$11="",0,IFERROR(INDEX(INDIRECT(S$6&VLOOKUP(Summary,Ref!$Y$13:$AC$18,3,FALSE)),MATCH(IF($P19="At Issue",VLOOKUP(Summary,Ref!$Y$13:$AC$18,2,FALSE),$P19),INDIRECT(S$6&VLOOKUP(Summary,Ref!$Y$13:$AC$18,4,FALSE)),0),VLOOKUP(S$10,Ref!$Y$61:$AA$63,2,FALSE)),0)))} -> #REF! | T19: {=IF($P19="","",IF(T$11="",0,IFERROR(INDEX(INDIRECT(T$6&VLOOKUP(Summary,Ref!$Y$13:$AC$18,3,FALSE)),MATCH(IF($P19="At Issue",VLOOKUP(Summary,Ref!$Y$13:$AC$18,2,FALSE),$P19),INDIRECT(T$6&VLOOKUP(Summary,Ref!$Y$13:$AC$18,4,FALSE)),0),VLOOKUP(T$10,Ref!$Y$61:$AA$63,2,FALSE)),0)))} -> #REF! | U19: {=IF($P19="","",IF(U$11="",0,IFERROR(INDEX(INDIRECT(U$6&VLOOKUP(Summary,Ref!$Y$13:$AC$18,3,FALSE)),MATCH(IF($P19="At Issue",VLOOKUP(Summary,Ref!$Y$13:$AC$18,2,FALSE),$P19),INDIRECT(U$6&VLOOKUP(Summary,Ref!$Y$13:$AC$18,4,FALSE)),0),VLOOKUP(U$10,Ref!$Y$61:$AA$63,2,FALSE)),0)))} -> #REF! | V19: {=IF($P19="","",IF(V$11="",0,IFERROR(INDEX(INDIRECT(V$6&VLOOKUP(Summary,Ref!$Y$13:$AC$18,3,FALSE)),MATCH(IF($P19="At Issue",VLOOKUP(Summary,Ref!$Y$13:$AC$18,2,FALSE),$P19),INDIRECT(V$6&VLOOKUP(Summary,Ref!$Y$13:$AC$18,4,FALSE)),0),VLOOKUP(V$10,Ref!$Y$61:$AA$63,2,FALSE)),0)))} -> #REF! | W19: {=IF($P19="","",IF(W$11="",0,IFERROR(INDEX(INDIRECT(W$6&VLOOKUP(Summary,Ref!$Y$13:$AC$18,3,FALSE)),MATCH(IF($P19="At Issue",VLOOKUP(Summary,Ref!$Y$13:$AC$18,2,FALSE),$P19),INDIRECT(W$6&VLOOKUP(Summary,Ref!$Y$13:$AC$18,4,FALSE)),0),VLOOKUP(W$10,Ref!$Y$61:$AA$63,2,FALSE)),0)))} -> #REF! | X19: =IF($P19="","",'Inputs & Summary'!S17) -> #REF! | Y19: =IF($P19="","",'Inputs & Summary'!T17) -> #REF! | Z19: =IF($P19="","",IF($Z$11="",0,'Inputs & Summary'!X17)) -> #REF! | AA19: =IF($P19="","",IF($AA$11="",0,IF(AND(LivBen<>"None",RIGHT(Category,2)<>"NY"),'Inputs & Summary'!AH17,""))) -> #REF! | AB19: =IF($P19="","",'Inputs & Summary'!Y17) -> #REF! | AC19: =IF($P19="","",IF(RIGHT(Category,2)="NY",'Inputs & Summary'!AH17,SUM('Inputs & Summary'!AB17,'Inputs & Summary'!AE17*('Inputs & Summary'!AD17="Yes"),'Inputs & Summary'!AG17))) -> #REF! | AD19: =IF($P19="","",'Inputs & Summary'!AI17) -> #REF! | AE19: =IF($P19="","",'Inputs & Summary'!Z17) -> #REF! | AF19: =IF($P19="","",'Inputs & Summary'!U17) -> #REF! | AG19: =IF($P19="","",'Inputs & Summary'!V17) -> #REF! | AH19: =IF($P19="","",'Inputs & Summary'!W17) -> #REF! | AI19: =IF($P19="","",IF($AI$11="",0,'Inputs & Summary'!AM17)) -> #REF! | AJ19: =IF($P19="","",IF($AJ$11="",0,IF(PTab="P7",'Inputs & Summary'!AQ17,'Inputs & Summary'!AA17))) -> #REF! | AK19: =IF($P19="","",'Inputs & Summary'!AJ17) -> #REF!
B20: =IF(PTab="P7","AICO Multiplier Rate",IF(Ref!$S$53="Y","GMAB Cadence","")) -> GMAB Cadence | C20: =IF(PTab="P7",OMR,IF(Ref!$S$53="Y",GMABC,"")) -> CDSC | F20: =IF($E20="","",INDEX([1]STRTG!$T$14:$AC$303,MATCH($E20,[1]STRTG!$P$14:$P$303,0),MATCH(F$5,[1]STRTG!$T$13:$AC$13,0))) | G20: =IF($E20="","",INDEX([1]STRTG!$T$14:$AC$303,MATCH($E20,[1]STRTG!$P$14:$P$303,0),MATCH(G$5,[1]STRTG!$T$13:$AC$13,0))) | H20: =IF($E20="","",INDEX([1]STRTG!$T$14:$AC$303,MATCH($E20,[1]STRTG!$P$14:$P$303,0),MATCH(H$5,[1]STRTG!$T$13:$AC$13,0))) | I20: =IF($E20="","",INDEX([1]STRTG!$T$14:$AC$303,MATCH($E20,[1]STRTG!$P$14:$P$303,0),MATCH(I$5,[1]STRTG!$T$13:$AC$13,0))) | J20: =IF($E20="","",INDEX([1]STRTG!$T$14:$AC$303,MATCH($E20,[1]STRTG!$P$14:$P$303,0),MATCH(J$5,[1]STRTG!$T$13:$AC$13,0))) | K20: =IF($E20="","",IF(RIGHT(VLOOKUP($E20,[1]STRTG!$P$14:$S$303,4,FALSE),6)="EPRST1",Ref!$C$103,IF(RIGHT(VLOOKUP($E20,[1]STRTG!$P$14:$S$303,4,FALSE),6)="EPRST2",Ref!$C$104,"N/A"))) | L20: =IF($E20="","",INDEX([1]STRTG!$T$14:$AC$303,MATCH($E20,[1]STRTG!$P$14:$P$303,0),MATCH(L$5,[1]STRTG!$T$13:$AC$13,0))) | P20: =IF('Inputs & Summary'!O18="","",IF('Inputs & Summary'!O18=0,"At Issue",'Inputs & Summary'!P18)) -> #REF! | Q20: =IF($P20="","",'Inputs & Summary'!O18) -> #REF! | R20: =IF($P20="","",'Inputs & Summary'!Q18) -> #REF! | S20: {=IF($P20="","",IF(S$11="",0,IFERROR(INDEX(INDIRECT(S$6&VLOOKUP(Summary,Ref!$Y$13:$AC$18,3,FALSE)),MATCH(IF($P20="At Issue",VLOOKUP(Summary,Ref!$Y$13:$AC$18,2,FALSE),$P20),INDIRECT(S$6&VLOOKUP(Summary,Ref!$Y$13:$AC$18,4,FALSE)),0),VLOOKUP(S$10,Ref!$Y$61:$AA$63,2,FALSE)),0)))} -> #REF! | T20: {=IF($P20="","",IF(T$11="",0,IFERROR(INDEX(INDIRECT(T$6&VLOOKUP(Summary,Ref!$Y$13:$AC$18,3,FALSE)),MATCH(IF($P20="At Issue",VLOOKUP(Summary,Ref!$Y$13:$AC$18,2,FALSE),$P20),INDIRECT(T$6&VLOOKUP(Summary,Ref!$Y$13:$AC$18,4,FALSE)),0),VLOOKUP(T$10,Ref!$Y$61:$AA$63,2,FALSE)),0)))} -> #REF! | U20: {=IF($P20="","",IF(U$11="",0,IFERROR(INDEX(INDIRECT(U$6&VLOOKUP(Summary,Ref!$Y$13:$AC$18,3,FALSE)),MATCH(IF($P20="At Issue",VLOOKUP(Summary,Ref!$Y$13:$AC$18,2,FALSE),$P20),INDIRECT(U$6&VLOOKUP(Summary,Ref!$Y$13:$AC$18,4,FALSE)),0),VLOOKUP(U$10,Ref!$Y$61:$AA$63,2,FALSE)),0)))} -> #REF! | V20: {=IF($P20="","",IF(V$11="",0,IFERROR(INDEX(INDIRECT(V$6&VLOOKUP(Summary,Ref!$Y$13:$AC$18,3,FALSE)),MATCH(IF($P20="At Issue",VLOOKUP(Summary,Ref!$Y$13:$AC$18,2,FALSE),$P20),INDIRECT(V$6&VLOOKUP(Summary,Ref!$Y$13:$AC$18,4,FALSE)),0),VLOOKUP(V$10,Ref!$Y$61:$AA$63,2,FALSE)),0)))} -> #REF! | W20: {=IF($P20="","",IF(W$11="",0,IFERROR(INDEX(INDIRECT(W$6&VLOOKUP(Summary,Ref!$Y$13:$AC$18,3,FALSE)),MATCH(IF($P20="At Issue",VLOOKUP(Summary,Ref!$Y$13:$AC$18,2,FALSE),$P20),INDIRECT(W$6&VLOOKUP(Summary,Ref!$Y$13:$AC$18,4,FALSE)),0),VLOOKUP(W$10,Ref!$Y$61:$AA$63,2,FALSE)),0)))} -> #REF! | X20: =IF($P20="","",'Inputs & Summary'!S18) -> #REF! | Y20: =IF($P20="","",'Inputs & Summary'!T18) -> #REF! | Z20: =IF($P20="","",IF($Z$11="",0,'Inputs & Summary'!X18)) -> #REF! | AA20: =IF($P20="","",IF($AA$11="",0,IF(AND(LivBen<>"None",RIGHT(Category,2)<>"NY"),'Inputs & Summary'!AH18,""))) -> #REF! | AB20: =IF($P20="","",'Inputs & Summary'!Y18) -> #REF! | AC20: =IF($P20="","",IF(RIGHT(Category,2)="NY",'Inputs & Summary'!AH18,SUM('Inputs & Summary'!AB18,'Inputs & Summary'!AE18*('Inputs & Summary'!AD18="Yes"),'Inputs & Summary'!AG18))) -> #REF! | AD20: =IF($P20="","",'Inputs & Summary'!AI18) -> #REF! | AE20: =IF($P20="","",'Inputs & Summary'!Z18) -> #REF! | AF20: =IF($P20="","",'Inputs & Summary'!U18) -> #REF! | AG20: =IF($P20="","",'Inputs & Summary'!V18) -> #REF! | AH20: =IF($P20="","",'Inputs & Summary'!W18) -> #REF! | AI20: =IF($P20="","",IF($AI$11="",0,'Inputs & Summary'!AM18)) -> #REF! | AJ20: =IF($P20="","",IF($AJ$11="",0,IF(PTab="P7",'Inputs & Summary'!AQ18,'Inputs & Summary'!AA18))) -> #REF! | AK20: =IF($P20="","",'Inputs & Summary'!AJ18) -> #REF!
B21: =IF(PTab="P7","AICO Maximum Rate","") | C21: =IF(PTab="P7",OMaxR,"") | F21: =IF($E21="","",INDEX([1]STRTG!$T$14:$AC$303,MATCH($E21,[1]STRTG!$P$14:$P$303,0),MATCH(F$5,[1]STRTG!$T$13:$AC$13,0))) | G21: =IF($E21="","",INDEX([1]STRTG!$T$14:$AC$303,MATCH($E21,[1]STRTG!$P$14:$P$303,0),MATCH(G$5,[1]STRTG!$T$13:$AC$13,0))) | H21: =IF($E21="","",INDEX([1]STRTG!$T$14:$AC$303,MATCH($E21,[1]STRTG!$P$14:$P$303,0),MATCH(H$5,[1]STRTG!$T$13:$AC$13,0))) | I21: =IF($E21="","",INDEX([1]STRTG!$T$14:$AC$303,MATCH($E21,[1]STRTG!$P$14:$P$303,0),MATCH(I$5,[1]STRTG!$T$13:$AC$13,0))) | J21: =IF($E21="","",INDEX([1]STRTG!$T$14:$AC$303,MATCH($E21,[1]STRTG!$P$14:$P$303,0),MATCH(J$5,[1]STRTG!$T$13:$AC$13,0))) | K21: =IF($E21="","",IF(RIGHT(VLOOKUP($E21,[1]STRTG!$P$14:$S$303,4,FALSE),6)="EPRST1",Ref!$C$103,IF(RIGHT(VLOOKUP($E21,[1]STRTG!$P$14:$S$303,4,FALSE),6)="EPRST2",Ref!$C$104,"N/A"))) | L21: =IF($E21="","",INDEX([1]STRTG!$T$14:$AC$303,MATCH($E21,[1]STRTG!$P$14:$P$303,0),MATCH(L$5,[1]STRTG!$T$13:$AC$13,0))) | P21: =IF('Inputs & Summary'!O19="","",IF('Inputs & Summary'!O19=0,"At Issue",'Inputs & Summary'!P19)) -> #REF! | Q21: =IF($P21="","",'Inputs & Summary'!O19) -> #REF! | R21: =IF($P21="","",'Inputs & Summary'!Q19) -> #REF! | S21: {=IF($P21="","",IF(S$11="",0,IFERROR(INDEX(INDIRECT(S$6&VLOOKUP(Summary,Ref!$Y$13:$AC$18,3,FALSE)),MATCH(IF($P21="At Issue",VLOOKUP(Summary,Ref!$Y$13:$AC$18,2,FALSE),$P21),INDIRECT(S$6&VLOOKUP(Summary,Ref!$Y$13:$AC$18,4,FALSE)),0),VLOOKUP(S$10,Ref!$Y$61:$AA$63,2,FALSE)),0)))} -> #REF! | T21: {=IF($P21="","",IF(T$11="",0,IFERROR(INDEX(INDIRECT(T$6&VLOOKUP(Summary,Ref!$Y$13:$AC$18,3,FALSE)),MATCH(IF($P21="At Issue",VLOOKUP(Summary,Ref!$Y$13:$AC$18,2,FALSE),$P21),INDIRECT(T$6&VLOOKUP(Summary,Ref!$Y$13:$AC$18,4,FALSE)),0),VLOOKUP(T$10,Ref!$Y$61:$AA$63,2,FALSE)),0)))} -> #REF! | U21: {=IF($P21="","",IF(U$11="",0,IFERROR(INDEX(INDIRECT(U$6&VLOOKUP(Summary,Ref!$Y$13:$AC$18,3,FALSE)),MATCH(IF($P21="At Issue",VLOOKUP(Summary,Ref!$Y$13:$AC$18,2,FALSE),$P21),INDIRECT(U$6&VLOOKUP(Summary,Ref!$Y$13:$AC$18,4,FALSE)),0),VLOOKUP(U$10,Ref!$Y$61:$AA$63,2,FALSE)),0)))} -> #REF! | V21: {=IF($P21="","",IF(V$11="",0,IFERROR(INDEX(INDIRECT(V$6&VLOOKUP(Summary,Ref!$Y$13:$AC$18,3,FALSE)),MATCH(IF($P21="At Issue",VLOOKUP(Summary,Ref!$Y$13:$AC$18,2,FALSE),$P21),INDIRECT(V$6&VLOOKUP(Summary,Ref!$Y$13:$AC$18,4,FALSE)),0),VLOOKUP(V$10,Ref!$Y$61:$AA$63,2,FALSE)),0)))} -> #REF! | W21: {=IF($P21="","",IF(W$11="",0,IFERROR(INDEX(INDIRECT(W$6&VLOOKUP(Summary,Ref!$Y$13:$AC$18,3,FALSE)),MATCH(IF($P21="At Issue",VLOOKUP(Summary,Ref!$Y$13:$AC$18,2,FALSE),$P21),INDIRECT(W$6&VLOOKUP(Summary,Ref!$Y$13:$AC$18,4,FALSE)),0),VLOOKUP(W$10,Ref!$Y$61:$AA$63,2,FALSE)),0)))} -> #REF! | X21: =IF($P21="","",'Inputs & Summary'!S19) -> #REF! | Y21: =IF($P21="","",'Inputs & Summary'!T19) -> #REF! | Z21: =IF($P21="","",IF($Z$11="",0,'Inputs & Summary'!X19)) -> #REF! | AA21: =IF($P21="","",IF($AA$11="",0,IF(AND(LivBen<>"None",RIGHT(Category,2)<>"NY"),'Inputs & Summary'!AH19,""))) -> #REF! | AB21: =IF($P21="","",'Inputs & Summary'!Y19) -> #REF! | AC21: =IF($P21="","",IF(RIGHT(Category,2)="NY",'Inputs & Summary'!AH19,SUM('Inputs & Summary'!AB19,'Inputs & Summary'!AE19*('Inputs & Summary'!AD19="Yes"),'Inputs & Summary'!AG19))) -> #REF! | AD21: =IF($P21="","",'Inputs & Summary'!AI19) -> #REF! | AE21: =IF($P21="","",'Inputs & Summary'!Z19) -> #REF! | AF21: =IF($P21="","",'Inputs & Summary'!U19) -> #REF! | AG21: =IF($P21="","",'Inputs & Summary'!V19) -> #REF! | AH21: =IF($P21="","",'Inputs & Summary'!W19) -> #REF! | AI21: =IF($P21="","",IF($AI$11="",0,'Inputs & Summary'!AM19)) -> #REF! | AJ21: =IF($P21="","",IF($AJ$11="",0,IF(PTab="P7",'Inputs & Summary'!AQ19,'Inputs & Summary'!AA19))) -> #REF! | AK21: =IF($P21="","",'Inputs & Summary'!AJ19) -> #REF!
F22: =IF($E22="","",INDEX([1]STRTG!$T$14:$AC$303,MATCH($E22,[1]STRTG!$P$14:$P$303,0),MATCH(F$5,[1]STRTG!$T$13:$AC$13,0))) | G22: =IF($E22="","",INDEX([1]STRTG!$T$14:$AC$303,MATCH($E22,[1]STRTG!$P$14:$P$303,0),MATCH(G$5,[1]STRTG!$T$13:$AC$13,0))) | H22: =IF($E22="","",INDEX([1]STRTG!$T$14:$AC$303,MATCH($E22,[1]STRTG!$P$14:$P$303,0),MATCH(H$5,[1]STRTG!$T$13:$AC$13,0))) | I22: =IF($E22="","",INDEX([1]STRTG!$T$14:$AC$303,MATCH($E22,[1]STRTG!$P$14:$P$303,0),MATCH(I$5,[1]STRTG!$T$13:$AC$13,0))) | J22: =IF($E22="","",INDEX([1]STRTG!$T$14:$AC$303,MATCH($E22,[1]STRTG!$P$14:$P$303,0),MATCH(J$5,[1]STRTG!$T$13:$AC$13,0))) | K22: =IF($E22="","",IF(RIGHT(VLOOKUP($E22,[1]STRTG!$P$14:$S$303,4,FALSE),6)="EPRST1",Ref!$C$103,IF(RIGHT(VLOOKUP($E22,[1]STRTG!$P$14:$S$303,4,FALSE),6)="EPRST2",Ref!$C$104,"N/A"))) | L22: =IF($E22="","",INDEX([1]STRTG!$T$14:$AC$303,MATCH($E22,[1]STRTG!$P$14:$P$303,0),MATCH(L$5,[1]STRTG!$T$13:$AC$13,0))) | P22: =IF('Inputs & Summary'!O20="","",IF('Inputs & Summary'!O20=0,"At Issue",'Inputs & Summary'!P20)) -> #REF! | Q22: =IF($P22="","",'Inputs & Summary'!O20) -> #REF! | R22: =IF($P22="","",'Inputs & Summary'!Q20) -> #REF! | S22: {=IF($P22="","",IF(S$11="",0,IFERROR(INDEX(INDIRECT(S$6&VLOOKUP(Summary,Ref!$Y$13:$AC$18,3,FALSE)),MATCH(IF($P22="At Issue",VLOOKUP(Summary,Ref!$Y$13:$AC$18,2,FALSE),$P22),INDIRECT(S$6&VLOOKUP(Summary,Ref!$Y$13:$AC$18,4,FALSE)),0),VLOOKUP(S$10,Ref!$Y$61:$AA$63,2,FALSE)),0)))} -> #REF! | T22: {=IF($P22="","",IF(T$11="",0,IFERROR(INDEX(INDIRECT(T$6&VLOOKUP(Summary,Ref!$Y$13:$AC$18,3,FALSE)),MATCH(IF($P22="At Issue",VLOOKUP(Summary,Ref!$Y$13:$AC$18,2,FALSE),$P22),INDIRECT(T$6&VLOOKUP(Summary,Ref!$Y$13:$AC$18,4,FALSE)),0),VLOOKUP(T$10,Ref!$Y$61:$AA$63,2,FALSE)),0)))} -> #REF! | U22: {=IF($P22="","",IF(U$11="",0,IFERROR(INDEX(INDIRECT(U$6&VLOOKUP(Summary,Ref!$Y$13:$AC$18,3,FALSE)),MATCH(IF($P22="At Issue",VLOOKUP(Summary,Ref!$Y$13:$AC$18,2,FALSE),$P22),INDIRECT(U$6&VLOOKUP(Summary,Ref!$Y$13:$AC$18,4,FALSE)),0),VLOOKUP(U$10,Ref!$Y$61:$AA$63,2,FALSE)),0)))} -> #REF! | V22: {=IF($P22="","",IF(V$11="",0,IFERROR(INDEX(INDIRECT(V$6&VLOOKUP(Summary,Ref!$Y$13:$AC$18,3,FALSE)),MATCH(IF($P22="At Issue",VLOOKUP(Summary,Ref!$Y$13:$AC$18,2,FALSE),$P22),INDIRECT(V$6&VLOOKUP(Summary,Ref!$Y$13:$AC$18,4,FALSE)),0),VLOOKUP(V$10,Ref!$Y$61:$AA$63,2,FALSE)),0)))} -> #REF! | W22: {=IF($P22="","",IF(W$11="",0,IFERROR(INDEX(INDIRECT(W$6&VLOOKUP(Summary,Ref!$Y$13:$AC$18,3,FALSE)),MATCH(IF($P22="At Issue",VLOOKUP(Summary,Ref!$Y$13:$AC$18,2,FALSE),$P22),INDIRECT(W$6&VLOOKUP(Summary,Ref!$Y$13:$AC$18,4,FALSE)),0),VLOOKUP(W$10,Ref!$Y$61:$AA$63,2,FALSE)),0)))} -> #REF! | X22: =IF($P22="","",'Inputs & Summary'!S20) -> #REF! | Y22: =IF($P22="","",'Inputs & Summary'!T20) -> #REF! | Z22: =IF($P22="","",IF($Z$11="",0,'Inputs & Summary'!X20)) -> #REF! | AA22: =IF($P22="","",IF($AA$11="",0,IF(AND(LivBen<>"None",RIGHT(Category,2)<>"NY"),'Inputs & Summary'!AH20,""))) -> #REF! | AB22: =IF($P22="","",'Inputs & Summary'!Y20) -> #REF! | AC22: =IF($P22="","",IF(RIGHT(Category,2)="NY",'Inputs & Summary'!AH20,SUM('Inputs & Summary'!AB20,'Inputs & Summary'!AE20*('Inputs & Summary'!AD20="Yes"),'Inputs & Summary'!AG20))) -> #REF! | AD22: =IF($P22="","",'Inputs & Summary'!AI20) -> #REF! | AE22: =IF($P22="","",'Inputs & Summary'!Z20) -> #REF! | AF22: =IF($P22="","",'Inputs & Summary'!U20) -> #REF! | AG22: =IF($P22="","",'Inputs & Summary'!V20) -> #REF! | AH22: =IF($P22="","",'Inputs & Summary'!W20) -> #REF! | AI22: =IF($P22="","",IF($AI$11="",0,'Inputs & Summary'!AM20)) -> #REF! | AJ22: =IF($P22="","",IF($AJ$11="",0,IF(PTab="P7",'Inputs & Summary'!AQ20,'Inputs & Summary'!AA20))) -> #REF! | AK22: =IF($P22="","",'Inputs & Summary'!AJ20) -> #REF!
B23: Living Benefit | C23: =LivBen -> None | F23: =IF($E23="","",INDEX([1]STRTG!$T$14:$AC$303,MATCH($E23,[1]STRTG!$P$14:$P$303,0),MATCH(F$5,[1]STRTG!$T$13:$AC$13,0))) | G23: =IF($E23="","",INDEX([1]STRTG!$T$14:$AC$303,MATCH($E23,[1]STRTG!$P$14:$P$303,0),MATCH(G$5,[1]STRTG!$T$13:$AC$13,0))) | H23: =IF($E23="","",INDEX([1]STRTG!$T$14:$AC$303,MATCH($E23,[1]STRTG!$P$14:$P$303,0),MATCH(H$5,[1]STRTG!$T$13:$AC$13,0))) | I23: =IF($E23="","",INDEX([1]STRTG!$T$14:$AC$303,MATCH($E23,[1]STRTG!$P$14:$P$303,0),MATCH(I$5,[1]STRTG!$T$13:$AC$13,0))) | J23: =IF($E23="","",INDEX([1]STRTG!$T$14:$AC$303,MATCH($E23,[1]STRTG!$P$14:$P$303,0),MATCH(J$5,[1]STRTG!$T$13:$AC$13,0))) | K23: =IF($E23="","",IF(RIGHT(VLOOKUP($E23,[1]STRTG!$P$14:$S$303,4,FALSE),6)="EPRST1",Ref!$C$103,IF(RIGHT(VLOOKUP($E23,[1]STRTG!$P$14:$S$303,4,FALSE),6)="EPRST2",Ref!$C$104,"N/A"))) | L23: =IF($E23="","",INDEX([1]STRTG!$T$14:$AC$303,MATCH($E23,[1]STRTG!$P$14:$P$303,0),MATCH(L$5,[1]STRTG!$T$13:$AC$13,0))) | P23: =IF('Inputs & Summary'!O21="","",IF('Inputs & Summary'!O21=0,"At Issue",'Inputs & Summary'!P21)) -> #REF! | Q23: =IF($P23="","",'Inputs & Summary'!O21) -> #REF! | R23: =IF($P23="","",'Inputs & Summary'!Q21) -> #REF! | S23: {=IF($P23="","",IF(S$11="",0,IFERROR(INDEX(INDIRECT(S$6&VLOOKUP(Summary,Ref!$Y$13:$AC$18,3,FALSE)),MATCH(IF($P23="At Issue",VLOOKUP(Summary,Ref!$Y$13:$AC$18,2,FALSE),$P23),INDIRECT(S$6&VLOOKUP(Summary,Ref!$Y$13:$AC$18,4,FALSE)),0),VLOOKUP(S$10,Ref!$Y$61:$AA$63,2,FALSE)),0)))} -> #REF! | T23: {=IF($P23="","",IF(T$11="",0,IFERROR(INDEX(INDIRECT(T$6&VLOOKUP(Summary,Ref!$Y$13:$AC$18,3,FALSE)),MATCH(IF($P23="At Issue",VLOOKUP(Summary,Ref!$Y$13:$AC$18,2,FALSE),$P23),INDIRECT(T$6&VLOOKUP(Summary,Ref!$Y$13:$AC$18,4,FALSE)),0),VLOOKUP(T$10,Ref!$Y$61:$AA$63,2,FALSE)),0)))} -> #REF! | U23: {=IF($P23="","",IF(U$11="",0,IFERROR(INDEX(INDIRECT(U$6&VLOOKUP(Summary,Ref!$Y$13:$AC$18,3,FALSE)),MATCH(IF($P23="At Issue",VLOOKUP(Summary,Ref!$Y$13:$AC$18,2,FALSE),$P23),INDIRECT(U$6&VLOOKUP(Summary,Ref!$Y$13:$AC$18,4,FALSE)),0),VLOOKUP(U$10,Ref!$Y$61:$AA$63,2,FALSE)),0)))} -> #REF! | V23: {=IF($P23="","",IF(V$11="",0,IFERROR(INDEX(INDIRECT(V$6&VLOOKUP(Summary,Ref!$Y$13:$AC$18,3,FALSE)),MATCH(IF($P23="At Issue",VLOOKUP(Summary,Ref!$Y$13:$AC$18,2,FALSE),$P23),INDIRECT(V$6&VLOOKUP(Summary,Ref!$Y$13:$AC$18,4,FALSE)),0),VLOOKUP(V$10,Ref!$Y$61:$AA$63,2,FALSE)),0)))} -> #REF! | W23: {=IF($P23="","",IF(W$11="",0,IFERROR(INDEX(INDIRECT(W$6&VLOOKUP(Summary,Ref!$Y$13:$AC$18,3,FALSE)),MATCH(IF($P23="At Issue",VLOOKUP(Summary,Ref!$Y$13:$AC$18,2,FALSE),$P23),INDIRECT(W$6&VLOOKUP(Summary,Ref!$Y$13:$AC$18,4,FALSE)),0),VLOOKUP(W$10,Ref!$Y$61:$AA$63,2,FALSE)),0)))} -> #REF! | X23: =IF($P23="","",'Inputs & Summary'!S21) -> #REF! | Y23: =IF($P23="","",'Inputs & Summary'!T21) -> #REF! | Z23: =IF($P23="","",IF($Z$11="",0,'Inputs & Summary'!X21)) -> #REF! | AA23: =IF($P23="","",IF($AA$11="",0,IF(AND(LivBen<>"None",RIGHT(Category,2)<>"NY"),'Inputs & Summary'!AH21,""))) -> #REF! | AB23: =IF($P23="","",'Inputs & Summary'!Y21) -> #REF! | AC23: =IF($P23="","",IF(RIGHT(Category,2)="NY",'Inputs & Summary'!AH21,SUM('Inputs & Summary'!AB21,'Inputs & Summary'!AE21*('Inputs & Summary'!AD21="Yes"),'Inputs & Summary'!AG21))) -> #REF! | AD23: =IF($P23="","",'Inputs & Summary'!AI21) -> #REF! | AE23: =IF($P23="","",'Inputs & Summary'!Z21) -> #REF! | AF23: =IF($P23="","",'Inputs & Summary'!U21) -> #REF! | AG23: =IF($P23="","",'Inputs & Summary'!V21) -> #REF! | AH23: =IF($P23="","",'Inputs & Summary'!W21) -> #REF! | AI23: =IF($P23="","",IF($AI$11="",0,'Inputs & Summary'!AM21)) -> #REF! | AJ23: =IF($P23="","",IF($AJ$11="",0,IF(PTab="P7",'Inputs & Summary'!AQ21,'Inputs & Summary'!AA21))) -> #REF! | AK23: =IF($P23="","",'Inputs & Summary'!AJ21) -> #REF!
B24: Withdrawal Type | C24: =IF(AND(RIGHT(Category,2)="NY",LivBen<>"None"),"GLIA",IF(LivBen<>"None","GMWB",IF(SWInd="No","None",SWMode))) -> None | F24: =IF($E24="","",INDEX([1]STRTG!$T$14:$AC$303,MATCH($E24,[1]STRTG!$P$14:$P$303,0),MATCH(F$5,[1]STRTG!$T$13:$AC$13,0))) | G24: =IF($E24="","",INDEX([1]STRTG!$T$14:$AC$303,MATCH($E24,[1]STRTG!$P$14:$P$303,0),MATCH(G$5,[1]STRTG!$T$13:$AC$13,0))) | H24: =IF($E24="","",INDEX([1]STRTG!$T$14:$AC$303,MATCH($E24,[1]STRTG!$P$14:$P$303,0),MATCH(H$5,[1]STRTG!$T$13:$AC$13,0))) | I24: =IF($E24="","",INDEX([1]STRTG!$T$14:$AC$303,MATCH($E24,[1]STRTG!$P$14:$P$303,0),MATCH(I$5,[1]STRTG!$T$13:$AC$13,0))) | J24: =IF($E24="","",INDEX([1]STRTG!$T$14:$AC$303,MATCH($E24,[1]STRTG!$P$14:$P$303,0),MATCH(J$5,[1]STRTG!$T$13:$AC$13,0))) | K24: =IF($E24="","",IF(RIGHT(VLOOKUP($E24,[1]STRTG!$P$14:$S$303,4,FALSE),6)="EPRST1",Ref!$C$103,IF(RIGHT(VLOOKUP($E24,[1]STRTG!$P$14:$S$303,4,FALSE),6)="EPRST2",Ref!$C$104,"N/A"))) | L24: =IF($E24="","",INDEX([1]STRTG!$T$14:$AC$303,MATCH($E24,[1]STRTG!$P$14:$P$303,0),MATCH(L$5,[1]STRTG!$T$13:$AC$13,0))) | P24: =IF('Inputs & Summary'!O22="","",IF('Inputs & Summary'!O22=0,"At Issue",'Inputs & Summary'!P22)) -> #REF! | Q24: =IF($P24="","",'Inputs & Summary'!O22) -> #REF! | R24: =IF($P24="","",'Inputs & Summary'!Q22) -> #REF! | S24: {=IF($P24="","",IF(S$11="",0,IFERROR(INDEX(INDIRECT(S$6&VLOOKUP(Summary,Ref!$Y$13:$AC$18,3,FALSE)),MATCH(IF($P24="At Issue",VLOOKUP(Summary,Ref!$Y$13:$AC$18,2,FALSE),$P24),INDIRECT(S$6&VLOOKUP(Summary,Ref!$Y$13:$AC$18,4,FALSE)),0),VLOOKUP(S$10,Ref!$Y$61:$AA$63,2,FALSE)),0)))} -> #REF! | T24: {=IF($P24="","",IF(T$11="",0,IFERROR(INDEX(INDIRECT(T$6&VLOOKUP(Summary,Ref!$Y$13:$AC$18,3,FALSE)),MATCH(IF($P24="At Issue",VLOOKUP(Summary,Ref!$Y$13:$AC$18,2,FALSE),$P24),INDIRECT(T$6&VLOOKUP(Summary,Ref!$Y$13:$AC$18,4,FALSE)),0),VLOOKUP(T$10,Ref!$Y$61:$AA$63,2,FALSE)),0)))} -> #REF! | U24: {=IF($P24="","",IF(U$11="",0,IFERROR(INDEX(INDIRECT(U$6&VLOOKUP(Summary,Ref!$Y$13:$AC$18,3,FALSE)),MATCH(IF($P24="At Issue",VLOOKUP(Summary,Ref!$Y$13:$AC$18,2,FALSE),$P24),INDIRECT(U$6&VLOOKUP(Summary,Ref!$Y$13:$AC$18,4,FALSE)),0),VLOOKUP(U$10,Ref!$Y$61:$AA$63,2,FALSE)),0)))} -> #REF! | V24: {=IF($P24="","",IF(V$11="",0,IFERROR(INDEX(INDIRECT(V$6&VLOOKUP(Summary,Ref!$Y$13:$AC$18,3,FALSE)),MATCH(IF($P24="At Issue",VLOOKUP(Summary,Ref!$Y$13:$AC$18,2,FALSE),$P24),INDIRECT(V$6&VLOOKUP(Summary,Ref!$Y$13:$AC$18,4,FALSE)),0),VLOOKUP(V$10,Ref!$Y$61:$AA$63,2,FALSE)),0)))} -> #REF! | W24: {=IF($P24="","",IF(W$11="",0,IFERROR(INDEX(INDIRECT(W$6&VLOOKUP(Summary,Ref!$Y$13:$AC$18,3,FALSE)),MATCH(IF($P24="At Issue",VLOOKUP(Summary,Ref!$Y$13:$AC$18,2,FALSE),$P24),INDIRECT(W$6&VLOOKUP(Summary,Ref!$Y$13:$AC$18,4,FALSE)),0),VLOOKUP(W$10,Ref!$Y$61:$AA$63,2,FALSE)),0)))} -> #REF! | X24: =IF($P24="","",'Inputs & Summary'!S22) -> #REF! | Y24: =IF($P24="","",'Inputs & Summary'!T22) -> #REF! | Z24: =IF($P24="","",IF($Z$11="",0,'Inputs & Summary'!X22)) -> #REF! | AA24: =IF($P24="","",IF($AA$11="",0,IF(AND(LivBen<>"None",RIGHT(Category,2)<>"NY"),'Inputs & Summary'!AH22,""))) -> #REF! | AB24: =IF($P24="","",'Inputs & Summary'!Y22) -> #REF! | AC24: =IF($P24="","",IF(RIGHT(Category,2)="NY",'Inputs & Summary'!AH22,SUM('Inputs & Summary'!AB22,'Inputs & Summary'!AE22*('Inputs & Summary'!AD22="Yes"),'Inputs & Summary'!AG22))) -> #REF! | AD24: =IF($P24="","",'Inputs & Summary'!AI22) -> #REF! | AE24: =IF($P24="","",'Inputs & Summary'!Z22) -> #REF! | AF24: =IF($P24="","",'Inputs & Summary'!U22) -> #REF! | AG24: =IF($P24="","",'Inputs & Summary'!V22) -> #REF! | AH24: =IF($P24="","",'Inputs & Summary'!W22) -> #REF! | AI24: =IF($P24="","",IF($AI$11="",0,'Inputs & Summary'!AM22)) -> #REF! | AJ24: =IF($P24="","",IF($AJ$11="",0,IF(PTab="P7",'Inputs & Summary'!AQ22,'Inputs & Summary'!AA22))) -> #REF! | AK24: =IF($P24="","",'Inputs & Summary'!AJ22) -> #REF!
